Workbook
Name door_frame: cena_dvere!$E$3
Name assembly: cena_dvere!$E$1
Name door_frame_sale: cena_dvere!$E$4
Name assembly_min: cena_dvere!$E$2

Sheet Hárok1
A1: STOLÁRSTVO | E1: MENO:
E2: TELEFÓN:
A3: SUČANSKÝ | E3: ADRESA:
E4: E-MAIL:
A5: CENOVÁ PONUKA INTERIÉROVÉ DVERE | E5: MATERIÁL:
A6: ROZMER | B6: MODEL | C6: MATERIÁL | D6: SKLO | E6: CENA / KS | F6: ZÁRUBEŇ | G6: KS | H6: CENA BEZ DPH
E7: =IFERROR(VLOOKUP(B7, cena_dvere!A:B, 2, FALSE), 0)+IF(A7<=69, 0,IF(A7<=79, 3,IF(A7<=89, 6, 9))) -> 0 | F7: Áno | H7: =IF(ISBLANK(B7),0, G7*E7+IF(F7="Áno", IF(B7="v1", door_frame_sale, door_frame), 0)) -> 0
E8: =IFERROR(VLOOKUP(B8, cena_dvere!A:B, 2, FALSE), 0)+IF(A8<=69, 0,IF(A8<=79, 3,IF(A8<=89, 6, 9))) -> 0 | F8: Áno | H8: =IF(ISBLANK(B8),0, G8*E8+IF(F8="Áno", IF(B8="v1", door_frame_sale, door_frame), 0)) -> 0
E9: =IFERROR(VLOOKUP(B9, cena_dvere!A:B, 2, FALSE), 0)+IF(A9<=69, 0,IF(A9<=79, 3,IF(A9<=89, 6, 9))) -> 0 | F9: Áno | H9: =IF(ISBLANK(B9),0, G9*E9+IF(F9="Áno", IF(B9="v1", door_frame_sale, door_frame), 0)) -> 0
E10: =IFERROR(VLOOKUP(B10, cena_dvere!A:B, 2, FALSE), 0)+IF(A10<=69, 0,IF(A10<=79, 3,IF(A10<=89, 6, 9))) -> 0 | F10: Áno | H10: =IF(ISBLANK(B10),0, G10*E10+IF(F10="Áno", IF(B10="v1", door_frame_sale, door_frame), 0)) -> 0
E11: =IFERROR(VLOOKUP(B11, cena_dvere!A:B, 2, FALSE), 0)+IF(A11<=69, 0,IF(A11<=79, 3,IF(A11<=89, 6, 9))) -> 0 | F11: Áno | H11: =IF(ISBLANK(B11),0, G11*E11+IF(F11="Áno", IF(B11="v1", door_frame_sale, door_frame), 0)) -> 0
E12: =IFERROR(VLOOKUP(B12, cena_dvere!A:B, 2, FALSE), 0)+IF(A12<=69, 0,IF(A12<=79, 3,IF(A12<=89, 6, 9))) -> 0 | F12: Áno | H12: =IF(ISBLANK(B12),0, G12*E12+IF(F12="Áno", IF(B12="v1", door_frame_sale, door_frame), 0)) -> 0
E13: =IFERROR(VLOOKUP(B13, cena_dvere!A:B, 2, FALSE), 0)+IF(A13<=69, 0,IF(A13<=79, 3,IF(A13<=89, 6, 9))) -> 0 | F13: Áno | H13: =IF(ISBLANK(B13),0, G13*E13+IF(F13="Áno", IF(B13="v1", door_frame_sale, door_frame), 0)) -> 0
E14: =IFERROR(VLOOKUP(B14, cena_dvere!A:B, 2, FALSE), 0)+IF(A14<=69, 0,IF(A14<=79, 3,IF(A14<=89, 6, 9))) -> 0 | F14: Áno | H14: =IF(ISBLANK(B14),0, G14*E14+IF(F14="Áno", IF(B14="v1", door_frame_sale, door_frame), 0)) -> 0
E15: =IFERROR(VLOOKUP(B15, cena_dvere!A:B, 2, FALSE), 0)+IF(A15<=69, 0,IF(A15<=79, 3,IF(A15<=89, 6, 9))) -> 0 | F15: Áno | H15: =IF(ISBLANK(B15),0, G15*E15+IF(F15="Áno", IF(B15="v1", door_frame_sale, door_frame), 0)) -> 0
A17: KĽUČKY nájdete na kluckynadvere.sk | F17: CENA / KS | G17: KS | H17: CENA BEZ DPH
H18: =G18*F18 -> 0
A19: Rozeta - BB štandardný interiérový zámok | F19: 0 | H19: =G19*F19 -> 0
A20: Rozeta - WC zámok | F20: 11 | H20: =G20*F20 -> 0
A21: Rozeta - FAB zámok | F21: 0 | H21: =G21*F21 -> 0
H22: =G22*F22 -> 0
A23: Montáž kľučiek a roziet 5€ | F23: 5 | H23: =G23*F23 -> 0
A25: DOVOZ | F25: MESTO | G25: KS | H25: CENA BEZ DPH
A26: Okresné mesto. Cena prepravy je 0,5 € za km. Preprava sa počíta od výroby v obci Čachtice. | H26: =G26
A27: Ulica
A28: Číslo domu
A29: Obec
A30: PSČ
A32: MONTÁŽ | G32: KS | H32: CENA BEZ DPH
A33: Akciová montáž dverí so zárubňou 35 € / kus. Akcia platí pri počte 6 a viac kusov. Minimálna suma na dvoch montážnikov je 210 €. | H33: =IF(G33>0,MAX(G33*assembly,assembly_min),0) -> 0
A35: ŠPECIÁLNE DOPLNKY | F35: CENA / KS | G35: KS | H35: CENA BEZ DPH
A36: Farebné krytky na pánty | F36: 12 | H36: =F36*G36 -> 0
A37: Farebné magnetické zámky | F37: 15 | H37: =F37*G37 -> 0
A38: Mušle na posuvné dvere | F38: 15 | H38: =F38*G38 -> 0
A39: Farebné skryté kovanie | H39: =F39*G39 -> 0
A40: Náprstník na posuvné dvere | F40: 10 | H40: =F40*G40 -> 0
A41: Príplatok za striekanie | H41: =F41*G41 -> 0
A42: Príplatok za dyhu | H42: =F42*G42 -> 0
A43: Príplatok za sklo | H43: =F43*G43 -> 0
A44: Vetracie mriežky do dverí | F44: 40 | H44: =F44*G44 -> 0
...

Sheet cena_dvere
A1: Code | B1: Price | D1: Assembly | E1: 35
A2: B1 | B2: 169 | D2: Assembly min | E2: 210
A3: B2 | B3: 169 | D3: Door frame | E3: 99
A4: B3 | B4: 169 | D4: Door frame sale | E4: 80
A5: B4 | B5: 169
A6: B5 | B6: 179
A7: B6 | B7: 219
A8: B7 | B8: 179
A9: B8 | B9: 179
A10: B9 | B10: 169
A11: B10 | B11: 169
A12: B11 | B12: 149
A13: B12 | B13: 169
A14: B13 | B14: 159
A15: B14 | B15: 159
A16: B15 | B16: 149
... A140: W3_L2_K2_O2_S | B140: 1119
